[23/May/2018 02:52:29] "GET /inputsong/ HTTP/1.1" 200 8671
[23/May/2018 02:52:31] "GET / HTTP/1.1" 200 8671
[23/May/2018 02:52:32] "GET / HTTP/1.1" 200 8671
Internal Server Error: /inputsong/
Traceback (most recent call last):
  File "/home/ubuntu/.local/lib/python3.5/site-packages/django/core/handlers/exception.py", line 35, in inner
    response = get_response(request)
  File "/home/ubuntu/.local/lib/python3.5/site-packages/django/core/handlers/base.py", line 128, in _get_response
    response = self.process_exception_by_middleware(e, request)
  File "/home/ubuntu/.local/lib/python3.5/site-packages/django/core/handlers/base.py", line 126, in _get_response
    response = wrapped_callback(request, *callback_args, **callback_kwargs)
  File "/var/www/SRS/picksong/views.py", line 14, in inputsong
    fo.write(request.POST.keys())
TypeError: write() argument must be str, not dict_keys
[23/May/2018 02:52:39] "POST /inputsong/ HTTP/1.1" 500 63346
Performing system checks...

System check identified no issues (0 silenced).
May 23, 2018 - 02:52:19
Django version 2.0.5, using settings 'SRS.settings'
Starting development server at http://0.0.0.0:8000/
Quit the server with CONTROL-C.
[23/May/2018 02:53:30] "GET / HTTP/1.1" 200 8671
[23/May/2018 02:53:38] "POST /inputsong/ HTTP/1.1" 200 8758
Performing system checks...

System check identified no issues (0 silenced).
May 23, 2018 - 02:53:23
Django version 2.0.5, using settings 'SRS.settings'
Starting development server at http://0.0.0.0:8000/
Quit the server with CONTROL-C.
Unhandled exception in thread started by <function check_errors.<locals>.wrapper at 0x7f4ac7f7f268>
Traceback (most recent call last):
  File "/home/ubuntu/.local/lib/python3.5/site-packages/django/utils/autoreload.py", line 225, in wrapper
    fn(*args, **kwargs)
  File "/home/ubuntu/.local/lib/python3.5/site-packages/django/core/management/commands/runserver.py", line 120, in inner_run
    self.check(display_num_errors=True)
  File "/home/ubuntu/.local/lib/python3.5/site-packages/django/core/management/base.py", line 364, in check
    include_deployment_checks=include_deployment_checks,
  File "/home/ubuntu/.local/lib/python3.5/site-packages/django/core/management/base.py", line 351, in _run_checks
    return checks.run_checks(**kwargs)
  File "/home/ubuntu/.local/lib/python3.5/site-packages/django/core/checks/registry.py", line 73, in run_checks
    new_errors = check(app_configs=app_configs)
  File "/home/ubuntu/.local/lib/python3.5/site-packages/django/core/checks/urls.py", line 13, in check_url_config
    return check_resolver(resolver)
  File "/home/ubuntu/.local/lib/python3.5/site-packages/django/core/checks/urls.py", line 23, in check_resolver
    return check_method()
  File "/home/ubuntu/.local/lib/python3.5/site-packages/django/urls/resolvers.py", line 397, in check
    for pattern in self.url_patterns:
  File "/home/ubuntu/.local/lib/python3.5/site-packages/django/utils/functional.py", line 36, in __get__
    res = instance.__dict__[self.name] = self.func(instance)
  File "/home/ubuntu/.local/lib/python3.5/site-packages/django/urls/resolvers.py", line 536, in url_patterns
    patterns = getattr(self.urlconf_module, "urlpatterns", self.urlconf_module)
  File "/home/ubuntu/.local/lib/python3.5/site-packages/django/utils/functional.py", line 36, in __get__
    res = instance.__dict__[self.name] = self.func(instance)
  File "/home/ubuntu/.local/lib/python3.5/site-packages/django/urls/resolvers.py", line 529, in urlconf_module
    return import_module(self.urlconf_name)
  File "/usr/lib/python3.5/importlib/__init__.py", line 126, in import_module
    return _bootstrap._gcd_import(name[level:], package, level)
  File "<frozen importlib._bootstrap>", line 986, in _gcd_import
  File "<frozen importlib._bootstrap>", line 969, in _find_and_load
  File "<frozen importlib._bootstrap>", line 958, in _find_and_load_unlocked
  File "<frozen importlib._bootstrap>", line 673, in _load_unlocked
  File "<frozen importlib._bootstrap_external>", line 665, in exec_module
  File "<frozen importlib._bootstrap>", line 222, in _call_with_frames_removed
  File "/var/www/SRS/SRS/urls.py", line 18, in <module>
    from picksong.views import hello_view
  File "/var/www/SRS/picksong/views.py", line 24
    return HttpResponseRedirect('')
                                  ^
IndentationError: unindent does not match any outer indentation level
Performing system checks...

[23/May/2018 03:10:43] "GET / HTTP/1.1" 200 8758
Internal Server Error: /inputsong/
Traceback (most recent call last):
  File "/home/ubuntu/.local/lib/python3.5/site-packages/django/core/handlers/exception.py", line 35, in inner
    response = get_response(request)
  File "/home/ubuntu/.local/lib/python3.5/site-packages/django/core/handlers/base.py", line 128, in _get_response
    response = self.process_exception_by_middleware(e, request)
  File "/home/ubuntu/.local/lib/python3.5/site-packages/django/core/handlers/base.py", line 126, in _get_response
    response = wrapped_callback(request, *callback_args, **callback_kwargs)
  File "/var/www/SRS/picksong/views.py", line 24, in inputsong
    return redirect('')
  File "/home/ubuntu/.local/lib/python3.5/site-packages/django/shortcuts.py", line 58, in redirect
    return redirect_class(resolve_url(to, *args, **kwargs))
  File "/home/ubuntu/.local/lib/python3.5/site-packages/django/shortcuts.py", line 149, in resolve_url
    return reverse(to, args=args, kwargs=kwargs)
  File "/home/ubuntu/.local/lib/python3.5/site-packages/django/urls/base.py", line 88, in reverse
    return iri_to_uri(resolver._reverse_with_prefix(view, prefix, *args, **kwargs))
  File "/home/ubuntu/.local/lib/python3.5/site-packages/django/urls/resolvers.py", line 632, in _reverse_with_prefix
    raise NoReverseMatch(msg)
django.urls.exceptions.NoReverseMatch: Reverse for '' not found. '' is not a valid view function or pattern name.
[23/May/2018 03:11:02] "POST /inputsong/ HTTP/1.1" 500 81780
Performing system checks...

System check identified no issues (0 silenced).
May 23, 2018 - 03:10:27
Django version 2.0.5, using settings 'SRS.settings'
Starting development server at http://0.0.0.0:8000/
Quit the server with CONTROL-C.
[23/May/2018 03:12:41] "GET / HTTP/1.1" 200 8845
[23/May/2018 03:12:42] "GET / HTTP/1.1" 200 8845
[23/May/2018 03:12:49] "POST /inputsong/ HTTP/1.1" 302 0
[23/May/2018 03:12:49] "GET / HTTP/1.1" 200 8932
[23/May/2018 03:13:12] "POST /inputsong/ HTTP/1.1" 302 0
[23/May/2018 03:13:13] "GET / HTTP/1.1" 200 9019
[23/May/2018 03:18:40] "GET / HTTP/1.1" 200 8584
Performing system checks...

System check identified no issues (0 silenced).
May 23, 2018 - 03:12:37
Django version 2.0.5, using settings 'SRS.settings'
Starting development server at http://0.0.0.0:8000/
Quit the server with CONTROL-C.
Unhandled exception in thread started by <function check_errors.<locals>.wrapper at 0x7f26b014c268>
Traceback (most recent call last):
  File "/home/ubuntu/.local/lib/python3.5/site-packages/django/utils/autoreload.py", line 225, in wrapper
    fn(*args, **kwargs)
  File "/home/ubuntu/.local/lib/python3.5/site-packages/django/core/management/commands/runserver.py", line 120, in inner_run
    self.check(display_num_errors=True)
  File "/home/ubuntu/.local/lib/python3.5/site-packages/django/core/management/base.py", line 364, in check
    include_deployment_checks=include_deployment_checks,
  File "/home/ubuntu/.local/lib/python3.5/site-packages/django/core/management/base.py", line 351, in _run_checks
    return checks.run_checks(**kwargs)
  File "/home/ubuntu/.local/lib/python3.5/site-packages/django/core/checks/registry.py", line 73, in run_checks
    new_errors = check(app_configs=app_configs)
  File "/home/ubuntu/.local/lib/python3.5/site-packages/django/core/checks/urls.py", line 13, in check_url_config
    return check_resolver(resolver)
  File "/home/ubuntu/.local/lib/python3.5/site-packages/django/core/checks/urls.py", line 23, in check_resolver
    return check_method()
  File "/home/ubuntu/.local/lib/python3.5/site-packages/django/urls/resolvers.py", line 397, in check
    for pattern in self.url_patterns:
  File "/home/ubuntu/.local/lib/python3.5/site-packages/django/utils/functional.py", line 36, in __get__
    res = instance.__dict__[self.name] = self.func(instance)
  File "/home/ubuntu/.local/lib/python3.5/site-packages/django/urls/resolvers.py", line 536, in url_patterns
    patterns = getattr(self.urlconf_module, "urlpatterns", self.urlconf_module)
  File "/home/ubuntu/.local/lib/python3.5/site-packages/django/utils/functional.py", line 36, in __get__
    res = instance.__dict__[self.name] = self.func(instance)
  File "/home/ubuntu/.local/lib/python3.5/site-packages/django/urls/resolvers.py", line 529, in urlconf_module
    return import_module(self.urlconf_name)
  File "/usr/lib/python3.5/importlib/__init__.py", line 126, in import_module
    return _bootstrap._gcd_import(name[level:], package, level)
  File "<frozen importlib._bootstrap>", line 986, in _gcd_import
  File "<frozen importlib._bootstrap>", line 969, in _find_and_load
  File "<frozen importlib._bootstrap>", line 958, in _find_and_load_unlocked
  File "<frozen importlib._bootstrap>", line 673, in _load_unlocked
  File "<frozen importlib._bootstrap_external>", line 665, in exec_module
  File "<frozen importlib._bootstrap>", line 222, in _call_with_frames_removed
  File "/var/www/SRS/SRS/urls.py", line 18, in <module>
    from picksong.views import hello_view
  File "/var/www/SRS/picksong/views.py", line 22
    if(songname is not "null")
                             ^
SyntaxError: invalid syntax
Performing system checks...

Unhandled exception in thread started by <function check_errors.<locals>.wrapper at 0x7fd9a3769268>
Traceback (most recent call last):
  File "/home/ubuntu/.local/lib/python3.5/site-packages/django/utils/autoreload.py", line 225, in wrapper
    fn(*args, **kwargs)
  File "/home/ubuntu/.local/lib/python3.5/site-packages/django/core/management/commands/runserver.py", line 120, in inner_run
    self.check(display_num_errors=True)
  File "/home/ubuntu/.local/lib/python3.5/site-packages/django/core/management/base.py", line 364, in check
    include_deployment_checks=include_deployment_checks,
  File "/home/ubuntu/.local/lib/python3.5/site-packages/django/core/management/base.py", line 351, in _run_checks
    return checks.run_checks(**kwargs)
  File "/home/ubuntu/.local/lib/python3.5/site-packages/django/core/checks/registry.py", line 73, in run_checks
    new_errors = check(app_configs=app_configs)
  File "/home/ubuntu/.local/lib/python3.5/site-packages/django/core/checks/urls.py", line 13, in check_url_config
    return check_resolver(resolver)
  File "/home/ubuntu/.local/lib/python3.5/site-packages/django/core/checks/urls.py", line 23, in check_resolver
    return check_method()
  File "/home/ubuntu/.local/lib/python3.5/site-packages/django/urls/resolvers.py", line 397, in check
    for pattern in self.url_patterns:
  File "/home/ubuntu/.local/lib/python3.5/site-packages/django/utils/functional.py", line 36, in __get__
    res = instance.__dict__[self.name] = self.func(instance)
  File "/home/ubuntu/.local/lib/python3.5/site-packages/django/urls/resolvers.py", line 536, in url_patterns
    patterns = getattr(self.urlconf_module, "urlpatterns", self.urlconf_module)
  File "/home/ubuntu/.local/lib/python3.5/site-packages/django/utils/functional.py", line 36, in __get__
    res = instance.__dict__[self.name] = self.func(instance)
  File "/home/ubuntu/.local/lib/python3.5/site-packages/django/urls/resolvers.py", line 529, in urlconf_module
    return import_module(self.urlconf_name)
  File "/usr/lib/python3.5/importlib/__init__.py", line 126, in import_module
    return _bootstrap._gcd_import(name[level:], package, level)
  File "<frozen importlib._bootstrap>", line 986, in _gcd_import
  File "<frozen importlib._bootstrap>", line 969, in _find_and_load
  File "<frozen importlib._bootstrap>", line 958, in _find_and_load_unlocked
  File "<frozen importlib._bootstrap>", line 673, in _load_unlocked
  File "<frozen importlib._bootstrap_external>", line 665, in exec_module
  File "<frozen importlib._bootstrap>", line 222, in _call_with_frames_removed
  File "/var/www/SRS/SRS/urls.py", line 18, in <module>
    from picksong.views import hello_view
  File "/var/www/SRS/picksong/views.py", line 19
    if(songname is not "null")
                             ^
SyntaxError: invalid syntax
Performing system checks...

Unhandled exception in thread started by <function check_errors.<locals>.wrapper at 0x7f2e6ceab268>
Traceback (most recent call last):
  File "/home/ubuntu/.local/lib/python3.5/site-packages/django/utils/autoreload.py", line 225, in wrapper
    fn(*args, **kwargs)
  File "/home/ubuntu/.local/lib/python3.5/site-packages/django/core/management/commands/runserver.py", line 120, in inner_run
    self.check(display_num_errors=True)
  File "/home/ubuntu/.local/lib/python3.5/site-packages/django/core/management/base.py", line 364, in check
    include_deployment_checks=include_deployment_checks,
  File "/home/ubuntu/.local/lib/python3.5/site-packages/django/core/management/base.py", line 351, in _run_checks
    return checks.run_checks(**kwargs)
  File "/home/ubuntu/.local/lib/python3.5/site-packages/django/core/checks/registry.py", line 73, in run_checks
    new_errors = check(app_configs=app_configs)
  File "/home/ubuntu/.local/lib/python3.5/site-packages/django/core/checks/urls.py", line 13, in check_url_config
    return check_resolver(resolver)
  File "/home/ubuntu/.local/lib/python3.5/site-packages/django/core/checks/urls.py", line 23, in check_resolver
    return check_method()
  File "/home/ubuntu/.local/lib/python3.5/site-packages/django/urls/resolvers.py", line 397, in check
    for pattern in self.url_patterns:
  File "/home/ubuntu/.local/lib/python3.5/site-packages/django/utils/functional.py", line 36, in __get__
    res = instance.__dict__[self.name] = self.func(instance)
  File "/home/ubuntu/.local/lib/python3.5/site-packages/django/urls/resolvers.py", line 536, in url_patterns
    patterns = getattr(self.urlconf_module, "urlpatterns", self.urlconf_module)
  File "/home/ubuntu/.local/lib/python3.5/site-packages/django/utils/functional.py", line 36, in __get__
    res = instance.__dict__[self.name] = self.func(instance)
  File "/home/ubuntu/.local/lib/python3.5/site-packages/django/urls/resolvers.py", line 529, in urlconf_module
    return import_module(self.urlconf_name)
  File "/usr/lib/python3.5/importlib/__init__.py", line 126, in import_module
    return _bootstrap._gcd_import(name[level:], package, level)
  File "<frozen importlib._bootstrap>", line 986, in _gcd_import
  File "<frozen importlib._bootstrap>", line 969, in _find_and_load
  File "<frozen importlib._bootstrap>", line 958, in _find_and_load_unlocked
  File "<frozen importlib._bootstrap>", line 673, in _load_unlocked
  File "<frozen importlib._bootstrap_external>", line 665, in exec_module
  File "<frozen importlib._bootstrap>", line 222, in _call_with_frames_removed
  File "/var/www/SRS/SRS/urls.py", line 18, in <module>
    from picksong.views import hello_view
  File "/var/www/SRS/picksong/views.py", line 19
    if songname is not "null"
                            ^
SyntaxError: invalid syntax
Performing system checks...

Unhandled exception in thread started by <function check_errors.<locals>.wrapper at 0x7f36c0b4a268>
Traceback (most recent call last):
  File "/home/ubuntu/.local/lib/python3.5/site-packages/django/utils/autoreload.py", line 225, in wrapper
    fn(*args, **kwargs)
  File "/home/ubuntu/.local/lib/python3.5/site-packages/django/core/management/commands/runserver.py", line 120, in inner_run
    self.check(display_num_errors=True)
  File "/home/ubuntu/.local/lib/python3.5/site-packages/django/core/management/base.py", line 364, in check
    include_deployment_checks=include_deployment_checks,
  File "/home/ubuntu/.local/lib/python3.5/site-packages/django/core/management/base.py", line 351, in _run_checks
    return checks.run_checks(**kwargs)
  File "/home/ubuntu/.local/lib/python3.5/site-packages/django/core/checks/registry.py", line 73, in run_checks
    new_errors = check(app_configs=app_configs)
  File "/home/ubuntu/.local/lib/python3.5/site-packages/django/core/checks/urls.py", line 13, in check_url_config
    return check_resolver(resolver)
  File "/home/ubuntu/.local/lib/python3.5/site-packages/django/core/checks/urls.py", line 23, in check_resolver
    return check_method()
  File "/home/ubuntu/.local/lib/python3.5/site-packages/django/urls/resolvers.py", line 397, in check
    for pattern in self.url_patterns:
  File "/home/ubuntu/.local/lib/python3.5/site-packages/django/utils/functional.py", line 36, in __get__
    res = instance.__dict__[self.name] = self.func(instance)
  File "/home/ubuntu/.local/lib/python3.5/site-packages/django/urls/resolvers.py", line 536, in url_patterns
    patterns = getattr(self.urlconf_module, "urlpatterns", self.urlconf_module)
  File "/home/ubuntu/.local/lib/python3.5/site-packages/django/utils/functional.py", line 36, in __get__
    res = instance.__dict__[self.name] = self.func(instance)
  File "/home/ubuntu/.local/lib/python3.5/site-packages/django/urls/resolvers.py", line 529, in urlconf_module
    return import_module(self.urlconf_name)
  File "/usr/lib/python3.5/importlib/__init__.py", line 126, in import_module
    return _bootstrap._gcd_import(name[level:], package, level)
  File "<frozen importlib._bootstrap>", line 986, in _gcd_import
  File "<frozen importlib._bootstrap>", line 969, in _find_and_load
  File "<frozen importlib._bootstrap>", line 958, in _find_and_load_unlocked
  File "<frozen importlib._bootstrap>", line 673, in _load_unlocked
  File "<frozen importlib._bootstrap_external>", line 665, in exec_module
  File "<frozen importlib._bootstrap>", line 222, in _call_with_frames_removed
  File "/var/www/SRS/SRS/urls.py", line 21, in <module>
    path('/', picksong),
NameError: name 'picksong' is not defined
Performing system checks...

System check identified some issues:

WARNINGS:
?: (urls.W002) Your URL pattern '/' has a route beginning with a '/'. Remove this slash as it is unnecessary. If this pattern is targeted in an include(), ensure the include() pattern has a trailing '/'.
?: (urls.W002) Your URL pattern '/hello1/' has a route beginning with a '/'. Remove this slash as it is unnecessary. If this pattern is targeted in an include(), ensure the include() pattern has a trailing '/'.
?: (urls.W002) Your URL pattern '/inputsong/' has a route beginning with a '/'. Remove this slash as it is unnecessary. If this pattern is targeted in an include(), ensure the include() pattern has a trailing '/'.

System check identified 3 issues (0 silenced).
Not Found: /picksong/
[23/May/2018 08:27:03] "GET /picksong/ HTTP/1.1" 404 2325
Not Found: /picksong/
[23/May/2018 08:27:10] "GET /picksong/ HTTP/1.1" 404 2325
Not Found: /
[23/May/2018 08:27:21] "GET / HTTP/1.1" 404 2280
Performing system checks...

May 23, 2018 - 08:27:00
Django version 2.0.5, using settings 'SRS.settings'
Starting development server at http://0.0.0.0:8000/
Quit the server with CONTROL-C.
System check identified some issues:

WARNINGS:
?: (urls.W002) Your URL pattern '/hello1/' has a route beginning with a '/'. Remove this slash as it is unnecessary. If this pattern is targeted in an include(), ensure the include() pattern has a trailing '/'.
?: (urls.W002) Your URL pattern '/inputsong/' has a route beginning with a '/'. Remove this slash as it is unnecessary. If this pattern is targeted in an include(), ensure the include() pattern has a trailing '/'.

System check identified 2 issues (0 silenced).
[23/May/2018 08:27:53] "GET / HTTP/1.1" 200 8583
Not Found: /inputsong
[23/May/2018 08:28:02] "POST /inputsong HTTP/1.1" 404 2325
Not Found: /picksong/
[23/May/2018 08:28:05] "GET /picksong/ HTTP/1.1" 404 2324
Performing system checks...

May 23, 2018 - 08:27:51
Django version 2.0.5, using settings 'SRS.settings'
Starting development server at http://0.0.0.0:8000/
Quit the server with CONTROL-C.
Internal Server Error: /inputsong
Traceback (most recent call last):
  File "/home/ubuntu/.local/lib/python3.5/site-packages/django/core/handlers/exception.py", line 35, in inner
    response = get_response(request)
  File "/home/ubuntu/.local/lib/python3.5/site-packages/django/utils/deprecation.py", line 93, in __call__
    response = self.process_request(request)
  File "/home/ubuntu/.local/lib/python3.5/site-packages/django/middleware/common.py", line 61, in process_request
    path = self.get_full_path_with_slash(request)
  File "/home/ubuntu/.local/lib/python3.5/site-packages/django/middleware/common.py", line 99, in get_full_path_with_slash
    'url': request.get_host() + new_path,
RuntimeError: You called this URL via POST, but the URL doesn't end in a slash and you have APPEND_SLASH set. Django can't redirect to the slash URL while maintaining POST data. Change your form to point to ec2-54-241-156-118.us-west-1.compute.amazonaws.com:8000/inputsong/ (note the trailing slash), or set APPEND_SLASH=False in your Django settings.
[23/May/2018 08:29:02] "POST /inputsong HTTP/1.1" 500 61920
Internal Server Error: /inputsong
Traceback (most recent call last):
  File "/home/ubuntu/.local/lib/python3.5/site-packages/django/core/handlers/exception.py", line 35, in inner
    response = get_response(request)
  File "/home/ubuntu/.local/lib/python3.5/site-packages/django/utils/deprecation.py", line 93, in __call__
    response = self.process_request(request)
  File "/home/ubuntu/.local/lib/python3.5/site-packages/django/middleware/common.py", line 61, in process_request
    path = self.get_full_path_with_slash(request)
  File "/home/ubuntu/.local/lib/python3.5/site-packages/django/middleware/common.py", line 99, in get_full_path_with_slash
    'url': request.get_host() + new_path,
RuntimeError: You called this URL via POST, but the URL doesn't end in a slash and you have APPEND_SLASH set. Django can't redirect to the slash URL while maintaining POST data. Change your form to point to ec2-54-241-156-118.us-west-1.compute.amazonaws.com:8000/inputsong/ (note the trailing slash), or set APPEND_SLASH=False in your Django settings.
[23/May/2018 08:30:01] "POST /inputsong HTTP/1.1" 500 61920
Not Found: /picksong/
[23/May/2018 08:31:27] "GET /picksong/ HTTP/1.1" 404 2321
Not Found: /picksong/
[23/May/2018 08:31:28] "GET /picksong/ HTTP/1.1" 404 2321
Not Found: /picksong/
[23/May/2018 08:33:37] "GET /picksong/ HTTP/1.1" 404 2321
[23/May/2018 08:34:24] "GET /inputsong/ HTTP/1.1" 200 8583
[23/May/2018 08:34:24] "GET / HTTP/1.1" 200 8583
[23/May/2018 08:34:24] "GET / HTTP/1.1" 200 8583
Internal Server Error: /inputsong
Traceback (most recent call last):
  File "/home/ubuntu/.local/lib/python3.5/site-packages/django/core/handlers/exception.py", line 35, in inner
    response = get_response(request)
  File "/home/ubuntu/.local/lib/python3.5/site-packages/django/utils/deprecation.py", line 93, in __call__
    response = self.process_request(request)
  File "/home/ubuntu/.local/lib/python3.5/site-packages/django/middleware/common.py", line 61, in process_request
    path = self.get_full_path_with_slash(request)
  File "/home/ubuntu/.local/lib/python3.5/site-packages/django/middleware/common.py", line 99, in get_full_path_with_slash
    'url': request.get_host() + new_path,
RuntimeError: You called this URL via POST, but the URL doesn't end in a slash and you have APPEND_SLASH set. Django can't redirect to the slash URL while maintaining POST data. Change your form to point to ec2-54-241-156-118.us-west-1.compute.amazonaws.com:8000/inputsong/ (note the trailing slash), or set APPEND_SLASH=False in your Django settings.
[23/May/2018 08:34:34] "POST /inputsong HTTP/1.1" 500 61920
[23/May/2018 08:35:39] "GET /inputsong/ HTTP/1.1" 200 8583
[23/May/2018 08:35:39] "GET / HTTP/1.1" 200 8583
[23/May/2018 08:35:39] "GET / HTTP/1.1" 200 8583
Not Found: /hello/
[23/May/2018 08:35:43] "GET /hello/ HTTP/1.1" 404 2312
Not Found: /hello/
[23/May/2018 08:35:43] "GET /hello/ HTTP/1.1" 404 2312
[23/May/2018 08:36:14] "GET / HTTP/1.1" 200 8583
[23/May/2018 08:36:15] "GET / HTTP/1.1" 200 8583
Performing system checks...

System check identified no issues (0 silenced).
May 23, 2018 - 08:28:54
Django version 2.0.5, using settings 'SRS.settings'
Starting development server at http://0.0.0.0:8000/
Quit the server with CONTROL-C.
[23/May/2018 08:36:44] "GET / HTTP/1.1" 200 8585
[23/May/2018 08:36:47] "GET /hello/ HTTP/1.1" 200 132
[23/May/2018 08:36:47] "GET /hello/ HTTP/1.1" 200 132
[23/May/2018 08:36:51] "GET / HTTP/1.1" 200 8585
Not Found: /picksong/
[23/May/2018 08:36:53] "GET /picksong/ HTTP/1.1" 404 2320
[23/May/2018 08:36:53] "GET /inputsong/ HTTP/1.1" 200 8585
[23/May/2018 08:36:54] "GET /inputsong/ HTTP/1.1" 200 8585
Internal Server Error: /inputsong/
Traceback (most recent call last):
  File "/home/ubuntu/.local/lib/python3.5/site-packages/django/core/handlers/exception.py", line 35, in inner
    response = get_response(request)
  File "/home/ubuntu/.local/lib/python3.5/site-packages/django/core/handlers/base.py", line 128, in _get_response
    response = self.process_exception_by_middleware(e, request)
  File "/home/ubuntu/.local/lib/python3.5/site-packages/django/core/handlers/base.py", line 126, in _get_response
    response = wrapped_callback(request, *callback_args, **callback_kwargs)
  File "/var/www/SRS/picksong/views.py", line 19, in inputsong
    if songname is not "null":
NameError: name 'songname' is not defined
[23/May/2018 08:37:04] "POST /inputsong/ HTTP/1.1" 500 63509
Performing system checks...

System check identified no issues (0 silenced).
May 23, 2018 - 08:36:41
Django version 2.0.5, using settings 'SRS.settings'
Starting development server at http://0.0.0.0:8000/
Quit the server with CONTROL-C.
[23/May/2018 08:37:55] "POST /inputsong/ HTTP/1.1" 200 8585
[23/May/2018 08:39:21] "POST /inputsong/ HTTP/1.1" 200 8585
[23/May/2018 08:40:31] "POST /inputsong/ HTTP/1.1" 200 8585
Performing system checks...

System check identified no issues (0 silenced).
May 23, 2018 - 08:37:51
Django version 2.0.5, using settings 'SRS.settings'
Starting development server at http://0.0.0.0:8000/
Quit the server with CONTROL-C.
[23/May/2018 08:42:56] "POST /inputsong/ HTTP/1.1" 200 8675
[23/May/2018 08:47:30] "POST /inputsong/ HTTP/1.1" 200 8765
[23/May/2018 12:42:06] "POST / HTTP/1.1" 200 9971
[23/May/2018 12:42:56] "POST / HTTP/1.1" 200 9971
[23/May/2018 12:43:48] "POST / HTTP/1.1" 200 10189
[23/May/2018 14:47:46] "GET / HTTP/1.1" 200 10106
[23/May/2018 14:47:49] "GET / HTTP/1.1" 200 10106
[23/May/2018 14:48:06] "GET / HTTP/1.1" 200 10106
[23/May/2018 14:48:45] "GET / HTTP/1.1" 200 10106
[23/May/2018 14:48:45] "GET / HTTP/1.1" 200 10106
[23/May/2018 14:49:58] "GET / HTTP/1.1" 200 10106
[23/May/2018 16:03:45] "GET / HTTP/1.1" 200 10106
[24/May/2018 05:25:40] "GET / HTTP/1.1" 200 10106
[24/May/2018 05:25:41] "GET / HTTP/1.1" 200 10106
[24/May/2018 05:25:55] "GET / HTTP/1.1" 200 10106
[24/May/2018 05:26:20] "GET / HTTP/1.1" 200 10106
[24/May/2018 05:59:01] "GET / HTTP/1.1" 200 10106
Not Found: /favicon.ico
[24/May/2018 05:59:03] "GET /favicon.ico HTTP/1.1" 404 2326
[24/May/2018 05:59:27] "GET / HTTP/1.1" 200 10106
Not Found: /favicon.ico
[24/May/2018 05:59:28] "GET /favicon.ico HTTP/1.1" 404 2326
[24/May/2018 06:08:36] "GET / HTTP/1.1" 200 10106
[24/May/2018 07:07:35] "GET / HTTP/1.1" 200 10106
Not Found: /picksong/
[24/May/2018 09:51:50] "GET /picksong/ HTTP/1.1" 404 2320
[24/May/2018 09:51:58] "GET / HTTP/1.1" 200 10106
[24/May/2018 09:53:25] "GET / HTTP/1.1" 200 10106
Traceback (most recent call last):
  File "/usr/lib/python3.5/socketserver.py", line 625, in process_request_thread
    self.finish_request(request, client_address)
  File "/usr/lib/python3.5/socketserver.py", line 354, in finish_request
    self.RequestHandlerClass(request, client_address, self)
  File "/usr/lib/python3.5/socketserver.py", line 681, in __init__
    self.handle()
  File "/home/ubuntu/.local/lib/python3.5/site-packages/django/core/servers/basehttp.py", line 139, in handle
    self.raw_requestline = self.rfile.readline(65537)
  File "/usr/lib/python3.5/socket.py", line 575, in readinto
    return self._sock.recv_into(b)
ConnectionResetError: [Errno 104] Connection reset by peer
[24/May/2018 13:17:46] "GET / HTTP/1.1" 200 10106
Not Found: /favicon.ico
[24/May/2018 13:17:47] "GET /favicon.ico HTTP/1.1" 404 2326
Performing system checks...

System check identified no issues (0 silenced).
May 23, 2018 - 12:41:18
Django version 2.0.5, using settings 'SRS.settings'
Starting development server at http://0.0.0.0:8000/
Quit the server with CONTROL-C.
----------------------------------------
Exception happened during processing of request from ('202.101.6.82', 56282)
----------------------------------------
[25/May/2018 02:59:41] "GET / HTTP/1.1" 200 10106
[25/May/2018 02:59:42] "GET / HTTP/1.1" 200 10106
[25/May/2018 02:59:42] "GET / HTTP/1.1" 200 10106
